Workbook

Sheet page 1
A1: Reference | B1: Qty | C1: codigo | D1: Descripcion Finengas | E1: Value | F1: Footprint
A2: C1,C2,C3,C4 | B2: 4 | C2: 60024300 | D2: =VLOOKUP(C2,codigo!A:B,2,FALSE) -> CAPACITOR ELECTROLITICO 10µF X 25V | E2: 10uF x 16V | F2: Capacitor_THT:CP_Radial_D5.0mm_P2.00mm
A3: C5,C6,C8,C9,C10,C11 | B3: 6 | C3: 60020011 | D3: =VLOOKUP(C3,codigo!A:B,2,FALSE) -> CAPACITOR CERAMICO .1µF | E3: 100nF Ceramico | F3: Capacitor_THT:C_Disc_D5.0mm_W2.5mm_P2.50mm
A4: C7 | B4: 1 | C4: 60024610 | D4: =VLOOKUP(C4,codigo!A:B,2,FALSE) -> CAPACITOR ELECTROLITICO 1000µF X 16/25V | E4: 1000uF x 16V electrolítico. | F4: Capacitor_THT:CP_Radial_D5.0mm_P2.50mm
A5: D1 | B5: 1 | C5: 60070010 | D5: =VLOOKUP(C5,codigo!A:B,2,FALSE) -> LED ROJO 5 MM | E5: LED Rojo 5mm | F5: LED_THT:LED_D5.0mm
A6: D2,D3 | B6: 2 | C6: 60070019 | D6: MV5439A LED bicolor red/green | E6: MV5439A | F6: LED_THT:LED_D5.0mm-3
A7: J2 | B7: 1 | C7: 60005001 | D7: =VLOOKUP(C7,codigo!A:B,2,FALSE) -> CONECTOR DB 9 HEMBRA P/IMPRESO | E7: DB9 Hembra Impreso 90° | F7: Connector_Dsub:DSUB-9_Socket_Horizontal_P2.77x2.84mm_EdgePinOffset4.94mm_Housed_MountingHolesOffset4.94mm
A8: J3 | B8: 1 | C8: 60004062 | D8: Conector Antena Ufl Smt - Smd X( U.FL macho para PCB(smd) | E8: U.FL IPEX1 MALE | F8: U.FL_Hirose_U.FL-R-SMT-1_Vertical
A9: J4 | B9: 1 | C9: 60004061 | D9: Conector SMA hembra Edge Mount (1.6 mm) (90° Impreso) | E9: SMA-J-P-X-RA-TH1 | F9: SMA-J-P-X-RA-TH1:SAMTEC_SMA-J-P-X-RA-TH1
A10: J5 | B10: 1 | C10: 60004063 | D10: Conector Barrel Jack DC 2.1mm PCB recto | E10: Barrel Jack DC 2.1mm PCB recto | F10: BarrelJack_CUI_PJ-102AH_Horizontal
A11: Q1, Q4 | B11: 2 | C11: 60050002 | D11: =VLOOKUP(C11,codigo!A:B,2,FALSE) -> TRANSISTOR BSS138 SMD | E11: BSS138 | F11: Package_TO_SOT_SMD:SOT-23
A12: Q2, Q3 | B12: 2 | C12: 60052021 | D12: =VLOOKUP(C12,codigo!A:B,2,FALSE) -> FDN340P MOSFET P-CH | E12: FDN340P | F12: Package_TO_SOT_SMD:SOT-23
A13: JP1 a JP7 | B13: 7 | C13: 60002025 | D13: =VLOOKUP(C13,codigo!A:B,2,FALSE) -> TIRA PINES RECTOS 1 X 40 | E13: Jumper 2 pines | F13: Connector_PinHeader_2.54mm:PinHeader_1x02_P2.54mm_Vertical
A14: R15,R17 | B14: 2 | C14: 60012909 | D14: =VLOOKUP(C14,codigo!A:B,2,FALSE) -> 150 OHM RESISTENCIA SMD Formato 0805 | E14: 150 | F14: Resistor_SMD:R_0805_2012Metric_Pad1.20x1.40mm_HandSolder
A15: R14,R16 | B15: 2 | C15: 60012918 | D15: =VLOOKUP(C15,codigo!A:B,2,FALSE) -> 220 OHM RESISTENCIA SMD Formato 0805 | E15: 220 | F15: Resistor_SMD:R_0805_2012Metric_Pad1.20x1.40mm_HandSolder
A16: R7, R12 | B16: 2 | C16: 60012910 | D16: =VLOOKUP(C16,codigo!A:B,2,FALSE) -> 1 KOHM RESISTENCIA SMD Formato 0805 | E16: 1K | F16: Resistor_SMD:R_0805_2012Metric_Pad1.20x1.40mm_HandSolder
A17: R1 | B17: 1 | C17: 60012917 | D17: =VLOOKUP(C17,codigo!A:B,2,FALSE) -> 2.2 KOHM RESISTENCIA SMD Formato 0805 | E17: 2K2 | F17: Resistor_SMD:R_0805_2012Metric_Pad1.20x1.40mm_HandSolder
A18: R2,R4,R9,R13 | B18: 4 | C18: 60012911 | D18: =VLOOKUP(C18,codigo!A:B,2,FALSE) -> RESISTENCIA 4,7 K SMD Formato 0805 | E18: 4K7 | F18: Resistor_SMD:R_0805_2012Metric_Pad1.20x1.40mm_HandSolder
A19: R3, R5, R8, R10 | B19: 4 | C19: 60012921 | D19: =VLOOKUP(C19,codigo!A:B,2,FALSE) -> RESISTENCIA 10 K SMD Formato 0805 | E19: 10K | F19: Resistor_SMD:R_0805_2012Metric_Pad1.20x1.40mm_HandSolder
A20: R6, R11 | B20: 2 | C20: 60012927 | D20: RESISTENCIA 100K SMD Formato 0805 | E20: 100K | F20: Resistor_SMD:R_0805_2012Metric_Pad1.20x1.40mm_HandSolder
A21: U1 | B21: 1 | C21: 60069101 | D21: =VLOOKUP(C21,codigo!A:B,2,FALSE) -> C.I. MAX232CSE SMD | E21: MAX232 | F21: Package_SO:SOIC-16_3.9x9.9mm_P1.27mm
A22: U2 | B22: 1 | C22: 60061005 | D22: =VLOOKUP(C22,codigo!A:B,2,FALSE) -> C.I.AT24C512-10PI MEMORIA EEPROM SERIAL 64KX8 ATME | E22: 24LC512 | F22: Package_SO:SOIC-8_3.9x4.9mm_P1.27mm
A23: U3 | B23: 1 | C23: 60069120 | D23: =VLOOKUP(C23,codigo!A:B,2,FALSE) -> MODULO MICRO TSIM SIMA A7670SA 4G V3 | E23: BKP-A7670SA (Módulo SIMCOM) | F23: Damian_PCB:SimCom_A7670SA
A24: U4 | B24: 1 | C24: 60069122 | D24: MAX706 SOIC8 | E24: MAX706 | F24: Package_SO:SOIC-8_3.9x4.9mm_P1.27mm
A25: U5 | B25: 1 | C25: 60069228 | D25: =VLOOKUP(C25,codigo!A:B,2,FALSE) -> PLACA STM32F401ccu6 ARM Cortex M4 84Mhz 256Kb | E25: Black_Pill_STM32F401CEU6 | F25: Damian_PCB:Black_Pill_STM32F401
A26: U6 | B26: 1 | C26: 70021626 | D26: =VLOOKUP(C26,codigo!A:B,2,FALSE) -> FUENTE STEP DOWN AJUSTABLE 1.25V A 35V LM2596 3A | E26: Step Down LM2596 | F26: Damian_PCB:Modulo Step Down Regulable LM2596
A27: U7 | B27: 1 | C27: 60069049 | D27: =VLOOKUP(C27,codigo!A:B,2,FALSE) -> C.I. MC7805ACT TO220 | E27: LM7805_TO220 | F27: Package_TO_SOT_THT:TO-220-3_Vertical
A28: Cable USSB-C to USB-micro-B (50092319) | C28: 50092319 | D28: =VLOOKUP(C28,codigo!A:B,2,FALSE) -> CABLE MICRO USB M a USBC M | E28: Cable USSB-C to USB-micro-B (50092319)
A29: Cable coaxial Pigtail RF RG178 IPX U.FL a IPX U.FL | C29: 60004064 | D29: Cable coaxial Pigtail RF RG178 IPX U.FL a IPX U.FL (15cm con conector plug en extremos) | E29: Cable coaxial Pigtail RF RG178 IPX U.FL a IPX U.FL
A30: Cable Pigtail coaxial antena 15cm de (U.FL IPX) a SMA hembra | C30: 60004065 | D30: Cable Pigtail U.fl Ipx A Sma Hembra Antena 15 Cm | E30: Cable Pigtail coaxial antena 15cm de (U.FL IPX) a SMA hembra

Sheet codigo
A1: pr_alias | B1: Articulo | C1: Stock Actual | D1: Posicion X | E1: Posicion Y | F1: Posicion Z | G1: Unidad | H1: Punto de Reposicion | I1: Solicitud de compra | J1: OC Sin Aprobar | K1: Orden de compra | L1: Solicitud de Tecnicos | M1: SOC Vs OC
A2: 1111609 | B2: TRAFO 220V a 220V 750 VA | C2: 0 | G2: Unidades | H2: 0 | I2: 0 | J2: 0 | K2: 0 | L2: 0 | M2: 0 | N2: 0
A3: 2021046 | B3: CAP.ELEC.470µF 16V 105° PC | C3: 0 | G3: Unidades | H3: 0 | I3: 0 | J3: 0 | K3: 0 | L3: 0 | M3: 0 | N3: 0
A4: 2021049 | B4: CAP.ELEC.470µF 6.3V 105° PC | C4: 0 | G4: Unidades | H4: 0 | I4: 0 | J4: 0 | K4: 0 | L4: 0 | M4: 0 | N4: 0
A5: 2121877 | B5: C.I. MC9S08sh8cp /J | C5: 0 | G5: Unidades | H5: 0 | I5: 0 | J5: 0 | K5: 0 | L5: 0 | M5: 0 | N5: 0
A6: 2181428 | B6: PLACA PTµC-MF | C6: 0 | G6: Unidades | H6: 0 | I6: 0 | J6: 0 | K6: 0 | L6: 0 | M6: 0 | N6: 0
A7: 2261458 | B7: 82 OHM RESISTENCIA 1/8 W | C7: 0 | D7: A | E7: 3 | F7: D/7 | G7: Unidades | H7: 0 | I7: 0 | J7: 0 | K7: 0 | L7: 0 | M7: 0 | N7: 0
A8: 3093050 | B8: BASTIDOR ABONADO DIGITAL PWR | C8: 0 | G8: Unidades | H8: 0 | I8: 0 | J8: 0 | K8: 0 | L8: 0 | M8: 0 | N8: 0
A9: 5052292 | B9: DISTRIBUIDOR 485 C485-4 4 SALIDAS | C9: 0 | G9: Unidades | H9: 0 | I9: 0 | J9: 0 | K9: 0 | L9: 0 | M9: 0 | N9: 0
A10: 5054153 | B10: RQS4-CPU-2 Replacement, multi-oop/display 2 annun | C10: 0 | G10: Unidades | H10: 0 | I10: 0 | J10: 0 | K10: 0 | L10: 0 | M10: 0 | N10: 0
A11: 10000000 | B11: LOGOTRON III | C11: 0 | D11: E | E11: 8 | F11: A/B | G11: Unidades | H11: 0 | I11: 0 | J11: 0 | K11: 0 | L11: 3 | M11: -3 | N11: -3
A12: 10000001 | B12: LOGOTRON III D | C12: 5 | D12: A | E12: 4 | G12: Unidades | H12: 0 | I12: 0 | J12: 0 | K12: 0 | L12: 8 | M12: -3 | N12: -3
A13: 10000002 | B13: LOGOTRON III D POWER 1 | C13: 1 | D13: A | E13: 4 | G13: Unidades | H13: 0 | I13: 0 | J13: 0 | K13: 0 | L13: 0 | M13: 1 | N13: 1
A14: 10000100 | B14: PROTECTOR TESOROµC - BR | C14: 64 | D14: B | E14: 15 | F14: C | G14: Unidades | H14: 0 | I14: 0 | J14: 0 | K14: 0 | L14: 15 | M14: 49 | N14: 49
A15: 10000101 | B15: PROTECTOR TESOROµC - MF | C15: 71 | D15: B | E15: 15 | F15: C | G15: Unidades | H15: 0 | I15: 0 | J15: 0 | K15: 0 | L15: 38 | M15: 33 | N15: 33
A16: 10000102 | B16: PROTECTOR TESORO µC - MSirena | C16: 30 | D16: B | E16: 15 | F16: E | G16: Unidades | H16: 0 | I16: 0 | J16: 0 | K16: 0 | L16: 1 | M16: 29 | N16: 29
A17: 10000103 | B17: PROTECTOR DE CASTILLETE | C17: 27 | D17: B | E17: 15 | F17: E | G17: Unidades | H17: 0 | I17: 0 | J17: 0 | K17: 0 | L17: 1 | M17: 26 | N17: 26
A18: 10000104 | B18: PROTECTOR DE CASTILLETE PDX | C18: 4 | D18: B | E18: 15 | F18: E | G18: Unidades | H18: 0 | I18: 0 | J18: 0 | K18: 0 | L18: 1 | M18: 3 | N18: 3
A19: 10000105 | B19: PROTECTOR TESORO EXPANSOR | C19: 7 | D19: B | E19: 15 | F19: E | G19: Unidades | H19: 0 | I19: 0 | J19: 0 | K19: 0 | L19: 2 | M19: 5 | N19: 5
A20: 10000106 | B20: PROTECTOR TESORO µC -MF-485 PT AVISADOR | C20: 0 | D20: B | E20: 15 | F20: E | G20: Unidades | H20: 0 | I20: 0 | J20: 0 | K20: 0 | L20: 0 | M20: 0 | N20: 0
A21: 10000150 | B21: MODULO DETECTOR PRESENCIA DE CASTILLETE | C21: 0 | D21: B | E21: 15 | F21: E | G21: Unidades | H21: 0 | I21: 0 | J21: 0 | K21: 0 | L21: 0 | M21: 0 | N21: 0
A22: 10000151 | B22: CAJA RELÉ PT µC - MSirena | C22: 35 | D22: B | E22: 15 | F22: E | G22: Unidades | H22: 0 | I22: 0 | J22: 0 | K22: 0 | L22: 1 | M22: 34 | N22: 34
A23: 10000152 | B23: MODULO DETECTOR PRESENCIA DE CASTILLETE PDX | C23: 1 | D23: B | E23: 15 | F23: E | G23: Unidades | H23: 0 | I23: 0 | J23: 0 | K23: 0 | L23: 0 | M23: 1 | N23: 1
A24: 10000153 | B24: CAJA REPARTIDORA PT | C24: 5 | D24: B | E24: 18 | F24: B | G24: Unidades | H24: 0 | I24: 0 | J24: 0 | K24: 0 | L24: 0 | M24: 5 | N24: 5
A25: 10000200 | B25: RABBIT POS | C25: 0 | G25: Unidades | H25: 0 | I25: 0 | J25: 0 | K25: 0 | L25: 0 | M25: 0 | N25: 0
A26: 10000201 | B26: RABBIT CON PESCADOR | C26: 4 | D26: B | E26: 20 | F26: F | G26: Unidades | H26: 0 | I26: 0 | J26: 0 | K26: 0 | L26: 0 | M26: 4 | N26: 4
A27: 10000202 | B27: RABBIT 2000 TCP/IP | C27: 0 | D27: E | E27: 15 | F27: A | G27: Unidades | H27: 0 | I27: 0 | J27: 0 | K27: 0 | L27: 0 | M27: 0 | N27: 0
A28: 10000203 | B28: RABBIT 3000 TCPIP | C28: 0 | D28: E | E28: 15 | F28: A | G28: Unidades | H28: 0 | I28: 0 | J28: 0 | K28: 0 | L28: 21 | M28: -21 | N28: -21
A29: 10000204 | B29: RABBIT 3200 TIPO M | C29: 114 | D29: B | E29: 19 | F29: D/E/F | G29: Unidades | H29: 0 | I29: 0 | J29: 0 | K29: 0 | L29: 13 | M29: 101 | N29: 101
A30: 10000300 | B30: ABONADO PAP | C30: 0 | D30: A | E30: 4 | G30: Unidades | H30: 0 | I30: 0 | J30: 0 | K30: 0 | L30: 0 | M30: 0 | N30: 0
A31: 10000301 | B31: ABONADO PAP C/RETRANSMISION | C31: 0 | D31: A | E31: 4 | G31: Unidades | H31: 0 | I31: 0 | J31: 0 | K31: 0 | L31: 0 | M31: 0 | N31: 0
A32: 10000310 | B32: COMISARIA PAP | C32: 3 | D32: A | E32: 4 | G32: Unidades | H32: 0 | I32: 0 | J32: 0 | K32: 0 | L32: 1 | M32: 2 | N32: 2
A33: 10000400 | B33: CENTRAL CLASE A DUAL | C33: 0 | G33: Unidades | H33: 0 | I33: 0 | J33: 0 | K33: 0 | L33: 1 | M33: -1 | N33: -1
A34: 10000410 | B34: CENTRAL CLASE B | C34: 5 | D34: A | E34: 4 | G34: Unidades | H34: 0 | I34: 0 | J34: 0 | K34: 0 | L34: 3 | M34: 2 | N34: 2
A35: 10000420 | B35: CENTRAL SIMIL A EN FORMATO CLASE B | C35: 0 | D35: A | E35: 4 | G35: Unidades | H35: 0 | I35: 0 | J35: 0 | K35: 0 | L35: 0 | M35: 0 | N35: 0
A36: 10000440 | B36: NODO DE USUARIO | C36: 0 | G36: Unidades | H36: 0 | I36: 0 | J36: 0 | K36: 0 | L36: 0 | M36: 0 | N36: 0
A37: 10000450 | B37: REPETIDORA SIMPLE | C37: 0 | D37: A | E37: 4 | G37: Unidades | H37: 0 | I37: 0 | J37: 0 | K37: 0 | L37: 0 | M37: 0 | N37: 0
A38: 10000451 | B38: REPETIDORA DOBLE | C38: 0 | G38: Unidades | H38: 0 | I38: 0 | J38: 0 | K38: 0 | L38: 0 | M38: 0 | N38: 0
A39: 10000500 | B39: PULSADOR ASALTO DIGITAL | C39: 566 | D39: B | E39: 15/6 | F39: A/A/BAJO MESA | G39: Unidades | H39: 0 | I39: 0 | J39: 0 | K39: 0 | L39: 31 | M39: 535 | N39: 535
A40: 10000501 | B40: PULSADOR ASALTO DIGITAL MODIFICADO HSBC | C40: 1 | D40: B | E40: 15 | F40: G | G40: Unidades | H40: 0 | I40: 0 | J40: 0 | K40: 0 | L40: 0 | M40: 1 | N40: 1
...

Sheet Hoja2
A1: pr_alias | B1: Articulo | C1: Stock Actual | D1: Posicion X | E1: Posicion Y | F1: Posicion Z | G1: Unidad | H1: Punto de Reposicion | I1: Solicitud de compra | J1: OC Sin Aprobar | K1: Orden de compra | L1: Solicitud de Tecnicos | M1: SOC Vs OC
A2: 1111609 | B2: TRAFO 220V a 220V 750 VA | C2: 0 | G2: Unidades | H2: 0 | I2: 0 | J2: 0 | K2: 0 | L2: 0 | M2: 0 | N2: 0
A3: 2021046 | B3: CAP.ELEC.470µF 16V 105° PC | C3: 0 | G3: Unidades | H3: 0 | I3: 0 | J3: 0 | K3: 0 | L3: 0 | M3: 0 | N3: 0
A4: 2021049 | B4: CAP.ELEC.470µF 6.3V 105° PC | C4: 0 | G4: Unidades | H4: 0 | I4: 0 | J4: 0 | K4: 0 | L4: 0 | M4: 0 | N4: 0
A5: 2121877 | B5: C.I. MC9S08sh8cp /J | C5: 0 | G5: Unidades | H5: 0 | I5: 0 | J5: 0 | K5: 0 | L5: 0 | M5: 0 | N5: 0
A6: 2181428 | B6: PLACA PTµC-MF | C6: 0 | G6: Unidades | H6: 0 | I6: 0 | J6: 0 | K6: 0 | L6: 0 | M6: 0 | N6: 0
A7: 2261458 | B7: 82 OHM RESISTENCIA 1/8 W | C7: 0 | D7: A | E7: 3 | F7: D/7 | G7: Unidades | H7: 0 | I7: 0 | J7: 0 | K7: 0 | L7: 0 | M7: 0 | N7: 0
A8: 3093050 | B8: BASTIDOR ABONADO DIGITAL PWR | C8: 0 | G8: Unidades | H8: 0 | I8: 0 | J8: 0 | K8: 0 | L8: 0 | M8: 0 | N8: 0
A9: 5052292 | B9: DISTRIBUIDOR 485 C485-4 4 SALIDAS | C9: 0 | G9: Unidades | H9: 0 | I9: 0 | J9: 0 | K9: 0 | L9: 0 | M9: 0 | N9: 0
A10: 5054153 | B10: RQS4-CPU-2 Replacement, multi-oop/display 2 annun | C10: 0 | G10: Unidades | H10: 0 | I10: 0 | J10: 0 | K10: 0 | L10: 0 | M10: 0 | N10: 0
A11: 10000000 | B11: LOGOTRON III | C11: 0 | D11: E | E11: 8 | F11: A/B | G11: Unidades | H11: 0 | I11: 0 | J11: 0 | K11: 0 | L11: 3 | M11: -3 | N11: -3
A12: 10000001 | B12: LOGOTRON III D | C12: 5 | D12: A | E12: 4 | G12: Unidades | H12: 0 | I12: 0 | J12: 0 | K12: 0 | L12: 8 | M12: -3 | N12: -3
A13: 10000002 | B13: LOGOTRON III D POWER 1 | C13: 1 | D13: A | E13: 4 | G13: Unidades | H13: 0 | I13: 0 | J13: 0 | K13: 0 | L13: 0 | M13: 1 | N13: 1
A14: 10000100 | B14: PROTECTOR TESOROµC - BR | C14: 64 | D14: B | E14: 15 | F14: C | G14: Unidades | H14: 0 | I14: 0 | J14: 0 | K14: 0 | L14: 15 | M14: 49 | N14: 49
A15: 10000101 | B15: PROTECTOR TESOROµC - MF | C15: 71 | D15: B | E15: 15 | F15: C | G15: Unidades | H15: 0 | I15: 0 | J15: 0 | K15: 0 | L15: 38 | M15: 33 | N15: 33
A16: 10000102 | B16: PROTECTOR TESORO µC - MSirena | C16: 30 | D16: B | E16: 15 | F16: E | G16: Unidades | H16: 0 | I16: 0 | J16: 0 | K16: 0 | L16: 1 | M16: 29 | N16: 29
A17: 10000103 | B17: PROTECTOR DE CASTILLETE | C17: 27 | D17: B | E17: 15 | F17: E | G17: Unidades | H17: 0 | I17: 0 | J17: 0 | K17: 0 | L17: 1 | M17: 26 | N17: 26
A18: 10000104 | B18: PROTECTOR DE CASTILLETE PDX | C18: 4 | D18: B | E18: 15 | F18: E | G18: Unidades | H18: 0 | I18: 0 | J18: 0 | K18: 0 | L18: 1 | M18: 3 | N18: 3
A19: 10000105 | B19: PROTECTOR TESORO EXPANSOR | C19: 7 | D19: B | E19: 15 | F19: E | G19: Unidades | H19: 0 | I19: 0 | J19: 0 | K19: 0 | L19: 2 | M19: 5 | N19: 5
A20: 10000106 | B20: PROTECTOR TESORO µC -MF-485 PT AVISADOR | C20: 0 | D20: B | E20: 15 | F20: E | G20: Unidades | H20: 0 | I20: 0 | J20: 0 | K20: 0 | L20: 0 | M20: 0 | N20: 0
A21: 10000150 | B21: MODULO DETECTOR PRESENCIA DE CASTILLETE | C21: 0 | D21: B | E21: 15 | F21: E | G21: Unidades | H21: 0 | I21: 0 | J21: 0 | K21: 0 | L21: 0 | M21: 0 | N21: 0
A22: 10000151 | B22: CAJA RELÉ PT µC - MSirena | C22: 35 | D22: B | E22: 15 | F22: E | G22: Unidades | H22: 0 | I22: 0 | J22: 0 | K22: 0 | L22: 1 | M22: 34 | N22: 34
A23: 10000152 | B23: MODULO DETECTOR PRESENCIA DE CASTILLETE PDX | C23: 1 | D23: B | E23: 15 | F23: E | G23: Unidades | H23: 0 | I23: 0 | J23: 0 | K23: 0 | L23: 0 | M23: 1 | N23: 1
A24: 10000153 | B24: CAJA REPARTIDORA PT | C24: 5 | D24: B | E24: 18 | F24: B | G24: Unidades | H24: 0 | I24: 0 | J24: 0 | K24: 0 | L24: 0 | M24: 5 | N24: 5
A25: 10000200 | B25: RABBIT POS | C25: 0 | G25: Unidades | H25: 0 | I25: 0 | J25: 0 | K25: 0 | L25: 0 | M25: 0 | N25: 0
A26: 10000201 | B26: RABBIT CON PESCADOR | C26: 4 | D26: B | E26: 20 | F26: F | G26: Unidades | H26: 0 | I26: 0 | J26: 0 | K26: 0 | L26: 0 | M26: 4 | N26: 4
A27: 10000202 | B27: RABBIT 2000 TCP/IP | C27: 0 | D27: E | E27: 15 | F27: A | G27: Unidades | H27: 0 | I27: 0 | J27: 0 | K27: 0 | L27: 0 | M27: 0 | N27: 0
A28: 10000203 | B28: RABBIT 3000 TCPIP | C28: 0 | D28: E | E28: 15 | F28: A | G28: Unidades | H28: 0 | I28: 0 | J28: 0 | K28: 0 | L28: 21 | M28: -21 | N28: -21
A29: 10000204 | B29: RABBIT 3200 TIPO M | C29: 114 | D29: B | E29: 19 | F29: D/E/F | G29: Unidades | H29: 0 | I29: 0 | J29: 0 | K29: 0 | L29: 13 | M29: 101 | N29: 101
A30: 10000300 | B30: ABONADO PAP | C30: 0 | D30: A | E30: 4 | G30: Unidades | H30: 0 | I30: 0 | J30: 0 | K30: 0 | L30: 0 | M30: 0 | N30: 0
A31: 10000301 | B31: ABONADO PAP C/RETRANSMISION | C31: 0 | D31: A | E31: 4 | G31: Unidades | H31: 0 | I31: 0 | J31: 0 | K31: 0 | L31: 0 | M31: 0 | N31: 0
A32: 10000310 | B32: COMISARIA PAP | C32: 3 | D32: A | E32: 4 | G32: Unidades | H32: 0 | I32: 0 | J32: 0 | K32: 0 | L32: 1 | M32: 2 | N32: 2
A33: 10000400 | B33: CENTRAL CLASE A DUAL | C33: 0 | G33: Unidades | H33: 0 | I33: 0 | J33: 0 | K33: 0 | L33: 1 | M33: -1 | N33: -1
A34: 10000410 | B34: CENTRAL CLASE B | C34: 5 | D34: A | E34: 4 | G34: Unidades | H34: 0 | I34: 0 | J34: 0 | K34: 0 | L34: 3 | M34: 2 | N34: 2
A35: 10000420 | B35: CENTRAL SIMIL A EN FORMATO CLASE B | C35: 0 | D35: A | E35: 4 | G35: Unidades | H35: 0 | I35: 0 | J35: 0 | K35: 0 | L35: 0 | M35: 0 | N35: 0
A36: 10000440 | B36: NODO DE USUARIO | C36: 0 | G36: Unidades | H36: 0 | I36: 0 | J36: 0 | K36: 0 | L36: 0 | M36: 0 | N36: 0
A37: 10000450 | B37: REPETIDORA SIMPLE | C37: 0 | D37: A | E37: 4 | G37: Unidades | H37: 0 | I37: 0 | J37: 0 | K37: 0 | L37: 0 | M37: 0 | N37: 0
A38: 10000451 | B38: REPETIDORA DOBLE | C38: 0 | G38: Unidades | H38: 0 | I38: 0 | J38: 0 | K38: 0 | L38: 0 | M38: 0 | N38: 0
A39: 10000500 | B39: PULSADOR ASALTO DIGITAL | C39: 566 | D39: B | E39: 15/6 | F39: A/A/BAJO MESA | G39: Unidades | H39: 0 | I39: 0 | J39: 0 | K39: 0 | L39: 31 | M39: 535 | N39: 535
A40: 10000501 | B40: PULSADOR ASALTO DIGITAL MODIFICADO HSBC | C40: 1 | D40: B | E40: 15 | F40: G | G40: Unidades | H40: 0 | I40: 0 | J40: 0 | K40: 0 | L40: 0 | M40: 1 | N40: 1
...
